Workbook

Sheet Survey report
A1: Jeewan deep Batta | I1: 17/102,royal estate
A2: Surveyor & Loss Assessor | I2: Zirakpur-140604
A3: License No. SLA-7777 Expirey: 26/10/2027 | I3: Mob: 9814035162
A4: IISLA No. F/N/05949 | I4: jd.batta8810@gmail.com
A6: Ref: | B6: JDB/2026-27/PORTAL-254654 | E6: MOTOR OD FINAL SURVEY REPORT | I6: Date: | J6: 01/09/2026
B7: The report is issued by me as Licenced surveyor without prejudice in respect of cause, nature & extent of loss/damages and subject to the terms and conditions of Insurance Policy.
A9: 1 | B9: INSURERS | F9: United India Insurance Company Limited
B10: ADDRESS | F10: NOT PRINTED
B12: COVER NOTE/POLICY NO. | E12: : | F12: 1103003122P113572944 | H12: Period: 00 | I12: 29-Mar-2024 to 28-Mar-2025
B13: CLAIM NO. | F13: 2230003126C065430001 | I13: IDV: | J13: NA | N13: workshop_invoice_no | P13: sfdf45s
A15: 2 | B15: INSURED | E15: : | F15: AJAY SINGH
B16: ADDRESS | E16: : | F16: B-27 JAGATPURI KRISHNA NAGAR EAST DELHI 110051
B17: CONTACT NO. | E17: : | F17: 8196088896 | N17: workshop_invoice_date | Q17: 45792
A19: 3 | B19: HPA WITH / FINANCER | E19: : | F19: NIL
A21: 4 | B21: VEHICLE PARTICULARS | E21: : | F21: RC Original Checked & Found In Order
B22: Registration No. | D22: / RTO | E22: : | F22: DL3SEK1646 | I22: SHEIKH SARAI
B23: Date of Registration issue | E23: : | F23: 06/09/2019
B24: Date of Registration expiry | E24: : | F24: 05/09/2034
B25: Chassis No | E25: : | F25: MAAZXFE1FKRT00073
B26: Engine No | E26: : | F26: ZXT00JE041637
B27: Make & Model | E27: : | F27: NINJA ZX-10R
B28: Type of Body | E28: : | F28: SOLO
B29: Class of Vehicle | E29: : | F29: M-Cycle/Scooter
B30: Pre-Accident Condition | E30: : | F30: Good
B31: Laden weight | D31: GVW | E31: :
B32: Unladen Weight | D32: ULW | E32: : | F32: 000206
B33: Approved Weight | F33: =IF(OR(F31="",F32=""),"",F31-F32)
B34: Fitness Cert. Valid upto | E34: : | F34: 05/09/2034
B35: Route Permit No. | E35: : | F35: NA
B36: Route Permit Validity | F36: NA
B37: Authorization No. | F37: NA
B38: Authorization Validity | E38: : | F38: NA
B39: Type of Permit | E39: : | F39: NA
B40: Route/area of Operation | E40: : | F40: Whole State
B41: Seating Capacity | E41: : | F41: 001
B42: Road Tax Paid Upto | E42: : | F42: OTT
B43: Fuel Used | E43: : | F43: PETROL
B44: Cubic Capacity | F44: 000998
B45: Colour | E45: : | F45: LIME GREEN
B46: Name of Regd. Owner as per RC | E46: : | F46: AJAY SINGH
...

Sheet Survey fee Bill
C2: ='Survey report'!A1 -> Jeewan deep Batta | J2: ='Survey report'!I1 -> 17/102,royal estate
C3: ='Survey report'!A2 -> Surveyor & Loss Assessor | J3: ='Survey report'!I2 -> Zirakpur-140604
C4: ='Survey report'!A3 -> License No. SLA-7777 Expirey: 26/10/2027 | J4: ='Survey report'!I3 -> Mob: 9814035162
C5: ='Survey report'!A4 -> IISLA No. F/N/05949 | J5: ='Survey report'!I4 -> jd.batta8810@gmail.com
C7: Ref: | D7: ='Survey report'!B6 -> JDB/2026-27/PORTAL-254654 | K7: Date: | L7: ='Survey report'!J6 -> 01/09/2026
F9: SURVEY FEE BILL
C12: INSURED | G12: ='Survey report'!F15 -> AJAY SINGH
G13: ='Survey report'!F16 -> B-27 JAGATPURI KRISHNA NAGAR EAST DELHI 110051
C15: INSURERS | G15: ='Survey report'!F9 -> United India Insurance Company Limited
G16: ='Survey report'!F10 -> NOT PRINTED
C17: GSTIN | F17: State code | G17: ='Survey report'!F11 -> 0 | H17: Punjab
C19: VEHICLE/ITEM | G19: ='Survey report'!F22 -> DL3SEK1646
C20: Make & Year of Manufacturer | G20: ='Survey report'!F27 -> NINJA ZX-10R
C22: C NOTE/POLICY NO. | G22: ='Survey report'!F12 -> 1103003122P113572944
C25: PROFESSIONAL FEE | G25: Rs | H25: =IF('Survey report'!H272<=20000,850,IF('Survey report'!H272<=50000,1500, IF('Survey report'!H272<100000,1800,IF('Survey report'!H272<=200000,2800,2800+(('Survey report'!H272-200000)*0.7%))))) -> 8439.281
C27: CONVEYANCE CHARGES | G27: Rs | H27: 500
C29: PHOTOGRAPHS | F29: 20 | G29: Rs | H29: 200
C31: DAILY ALLOWANCE | G31: Rs | H31: 0
C33: RE-INSPECTION | G33: Rs | H33: 1000
C35: MISC. | G35: RS
C37: TOTAL | G37: Rs | H37: =SUM(H25:H35) -> 10139.281
C38: CGST | E38: 0 | G38: RS | H38: =(E38*H37)/100 -> 0
C39: SGST/UTGST | E39: 0 | G39: RS | H39: =(E39*H37)/100 -> 0
C40: IGST | E40: 18 | G40: RS | H40: =(E40*H37)/100 -> 1825.0706
C42: Grand Total | H42: =SUM(H37:H40) -> 11964.352
C44: FOR NEFT PAYMENT | J44: ='Survey report'!A1 -> Jeewan deep Batta
C46: BANK ACCOUNT DETAILS | J46: Surveyor & Loss Assessor
C47: BANK NAME: | E47: NA
C48: A/C NUMBER: | E48: 06481000084955
C49: A/C TYPE: | E49: savingHDFC648
C50: IFSC CODE: | E50: HDFC648
C51: MICR CODE: | E51: 160013003
C52: GST No. | E52: NA
C53: State code | E53: 04

Sheet Re-inspection
B2: ='Survey report'!A1 -> Jeewan deep Batta | I2: ='Survey report'!I1 -> 17/102,royal estate
B3: ='Survey report'!A2 -> Surveyor & Loss Assessor | I3: ='Survey report'!I2 -> Zirakpur-140604
B4: ='Survey report'!A3 -> License No. SLA-7777 Expirey: 26/10/2027 | I4: ='Survey report'!I3 -> Mob: 9814035162
B5: ='Survey report'!A4 -> IISLA No. F/N/05949 | I5: ='Survey report'!I4 -> jd.batta8810@gmail.com
B8: Ref: | C8: ='Survey report'!B6 -> JDB/2026-27/PORTAL-254654 | I8: Date: | J8: ='Survey report'!J6 -> 01/09/2026
F9: Re-Inspection
C10: Insured | H10: ='Survey report'!F15 -> AJAY SINGH
C11: Policy No. | H11: ='Survey report'!F12 -> 1103003122P113572944
C12: Date of Survey | H12: ='Survey report'!F65 -> 45043
B14: PRIVATE & CONFIDENTIAL MOTOR RE-INSPECTION SURVEY REPORT
B17: I have re-inspected the captioned vehicle & have found that the repairs / or & replacements made there in were strictly followed as per our final survey report. I have also taken a few necessary photographs of the same along with the salvage parts. The vehicle re-inspected was found to be in road worthy condition at the time of my survey. As per the request of the insurer's we have also conducted the salvage destruction process during our re-inspection & also we have snapped a couple of photographs of the destructed salvage along with the vehicle for the verification of the same.
B21: The report is issued without prejudice
B23: ='Survey report'!A1 -> Jeewan deep Batta

Sheet Total Loss
B1: ='Survey report'!A1 -> Jeewan deep Batta | I1: ='Survey report'!I1 -> 17/102,royal estate
B2: ='Survey report'!A2 -> Surveyor & Loss Assessor | I2: ='Survey report'!I2 -> Zirakpur-140604
B3: ='Survey report'!A3 -> License No. SLA-7777 Expirey: 26/10/2027 | I3: =+'Survey report'!I3 -> Mob: 9814035162
B4: ='Survey report'!A4 -> IISLA No. F/N/05949 | I4: ='Survey report'!I4 -> jd.batta8810@gmail.com
B6: Ref: | C6: JDB/2026-27/PORTAL/8744 | F6: Total Loss/Net of Salvage | J6: ='Survey report'!J6 -> 01/09/2026
B7: The loss worked out as above is on the basiss of apperant damages & liability of the insurers may increase by another 10 /15 percent after dismantling of the vehicle thus enhancing the actual liability. So keeping in view the high cost of repairs with respect to the IDV of the vehicle, the other modes of assessment like total loss, net of salvage were also considered as under:
B15: REPAIR BASISS SETTLEMENT
B16: Loss assessed | H16: Rs. | I16: ='Survey report'!J272 -> 1.001143e+08
B17: Kept open Items | H17: RS. | I17: =(I16*10)/100 -> 10011430
B18: Expected Liability | H18: Rs. | I18: =I16+I17 -> 1.1012573e+08
B20: TOTAL LOSS SETTLEMENT :
A21: 1 | B21: Sum Assured | H21: Rs. | I21: NA
A22: 2 | B22: Indeminty Payable Mkt Value | H22: Rs. | I22: =I21 -> NA
A23: 3 | B23: Less Salvage of old Vehicle | H23: Rs.
A24: 4 | B24: Net Liability | H24: Rs. | I24: =I21-I23 -> #VALUE!
B26: NETT OF SALVAGE SETTLEMENT :
A27: 1 | B27: Total Loss Indeminity | H27: Rs. | I27: =I21 -> NA
A28: 2 | B28: Less Salvage of old Vehicle | H28: Rs.
A29: 3 | B29: Net Payable | H29: Rs. | I29: =I27-I28 -> #VALUE!
A30: 4 | B30: Net Liability | H30: Rs. | I30: =I29 -> #VALUE!
B32: CASH LOSS SETTLEMENT :
A33: 1 | B33: Indeminity Payable on Repair basis | H33: Rs. | I33: =I16 -> 1.001143e+08
A34: 2 | B34: Less Amount of GST on Parts | H34: Rs. | I34: =I16*18/100 -> 18020573
A35: 3 | B35: Reduced Liability | H35: Rs. | I35: =I33-I34 -> 82093723
A36: 6 | B36: Less 15% lumpsum Amount | H36: Rs. | I36: =I35*15/100 -> 12314058
A37: 7 | B37: Reduced Liability | H37: Rs. | I37: =I35-I36 -> 69779665
A40: So keeping in view the above modes, the "Net of Salvage" seems to be most apporopirate for both the stake holders & recommended for your kind consideration
I45: ='Survey report'!A1 -> Jeewan deep Batta
I47: ='Survey report'!A2 -> Surveyor & Loss Assessor

Sheet Appraisal
A1: Jeewan deep Batta | F1: ANNEXURE II | I1: 17/102,royal estate
A2: Surveyor & Loss Assessor | D2: Surveyor's Performance Appraisal (SPA) Form | I2: Zirakpur-140604
A3: License No. SLA-7777 Expirey: 26/10/2027 | I3: Mob: 9814035162
A4: IISLA No. F/N/05949 | B4: Office Code | E4: ='Survey report'!F12 -> 1103003122P113572944 | H4: Claim No. | I4: jd.batta8810@gmail.com
B5: Name of Office/Address | E5: ='Survey report'!F10 -> NOT PRINTED | H5: Insured | I5: ='Survey report'!F15 -> AJAY SINGH
B6: Name of Surveyor | E6: ='Survey report'!A1 -> Jeewan deep Batta | H6: Report No. | I6: ='Survey report'!B6 -> JDB/2026-27/PORTAL-254654
H7: IIISLA No. | I7: ='Survey report'!B6 -> JDB/2026-27/PORTAL-254654
B9: 1 | C9: Date of Loss: | H9: ='Survey report'!F60 -> 23/04/2023
B11: 2 | C11: Date of Appointment of Surveyor | H11: ='Survey report'!F64 -> 45041
B13: 3 | C13: Date of First Visit to site | H13: ='Survey report'!F65 -> 45043
B15: 4 | C15: Dates of document cpompletion
B17: 5 | C17: Date of Re-inspection | H17: ='Survey report'!J6 -> 01/09/2026
B19: 6 | C19: Date of submission of Final Report | H19: ='Survey report'!J6 -> 01/09/2026
B21: 7 | C21: Reasons for delay in submission of report, if any
B23: 8 | C23: Turn Around Time
B25: 9 | C25: Whether consent for assessment obtained from the Insured / Claimant | J25: yes
B27: 10 | C27: Number of times documents were requisitioned from the Insured (excluding reminders)
C28: (Whats app communication / Chat attached)
B30: 11 | C30: Remarks
B32: Place:_______________________ | I32: ='Survey report'!A1 -> Jeewan deep Batta
B33: Date:_______________________ | C33: ='Survey report'!J6 -> 01/09/2026 | I33: (Signature of the Surveyor)
B36: For Office use:-
B38: (to be filed in by the Claim Officer alongside settlement of each claim)
C39: Parameters | H39: Primary Claim Dealin | K39: Score
H40: Officer
C41: Timely submission of survey report | K41: 1-10
C42: (Please refer to Policy for marking)
C44: Error free and unambiguous survey report- | K44: 1-10
C45: Fair assessment
C47: Quick Response to queries raised, if any | K47: 1-10
C48: Suggenstion for risk improvement | K48: 1-10
C49: Feedback from the customer | K49: 1-10
B51: Ten point scale - Outstanding being (10) and Poor being ( 1 ):
B53: Signature: | E53: Designation | G53: Office | I53: Date
B55: Name:
