Workbook

Sheet Sheet1
B2: Er. SUNIL KUMAR | I2: # 304, Village: Daria,
B3: SURVEYOR & LOSS ASSESSOR | I3: Near Railway Station, Chandigarh
B4: LICENCE NO: 73070 EXPIRY: 08.02.2028 | I4: Mobile: 098761-35253
B5: PAN NO: AQUPK1480C | I5: e-mail:- ksunilsurveyor@gmail.com
B8: Ref: | C8: SK/2025-26/OICL/9873 | J8: Date:
B10: PRIVATE & CONFIDENTIAL SURVEY REPORT
B11: The report is issued by me as Licenced surveyor without prejudice in respect of cause, nature & extent of loss/damages and subject to the terms and conditions of Insurance Policy.
B12: 1
B13: a | C13: INSURERS | F13: : | G13: NA | J13: IDV= | K13: NA
C14: ADDRESS | F14: :
B16: b | C16: COVER NOTE/POLICY NO. | F16: : | G16: NA | J16: Period: | K16: NA | M16: Nil Depreciation | N16: yes
B18: c | C18: INSURED | F18: : | G18: NA
C19: ADDRESS | F19: : | G19: delhi
C20: CONTACT NO. | F20: : | G20: NA
B22: d | C22: HPA WITH | F22: : | G22: MAGMA FINCORP LTD
B24: 2 | C24: VEHICLE PARTICULARS | F24: : | G24: RC Original Checked & Found In Order
B25: a | C25: Registration No. | F25: : | G25: HR49H9873
B26: b | C26: Date of Registration issue | F26: : | G26: 20.11.2019
B27: c | C27: Date of Registration expiry | F27: : | G27: 19.11.2034
G28: Physically Checked | I28: As Per RC | K28: As Per Ins.
B29: d | C29: Chassis No | F29: : | G29: S00546022 | I29: =G29 -> S00546022 | K29: =G29 -> S00546022
B30: e | C30: Engine No | F30: : | G30: N8272201 | I30: =G30 -> N8272201 | K30: =G30 -> N8272201
B31: f | C31: Make & Year of Manufacturer | F31: : | G31: MARUTI ALTO K10 VXI
B32: g | C32: Type of Body | F32: : | G32: SALOON CAR
B33: h | C33: Class of Vehicle | F33: : | G33: Motor Car - NT
B34: i | C34: Pre-Accident Condition | F34: : | G34: Stated to be normal road worthy
B35: j | C35: Registered Laden Weight | F35: : | G35: 990
B36: k | C36: Unladen Weight | F36: : | G36: 9800
B37: l | C37: Fitness Cert Valid Upto | F37: : | G37: 19.11.2034
C38: Permit No. | F38: : | G38: NA
C39: Valid Upto | F39: : | G39: NA
C40: Type of Permit | F40: : | G40: NA
C41: Route/area of Operation | F41: : | G41: NA
B42: m | C42: Seating Capacity | F42: : | G42: 5
B43: n | C43: Road Tax Paid Upto | F43: : | G43: 19/11/2034 | J43: Fuel used: PETROL
B44: o | C44: Name of Regd. Owner as per RC | F44: : | G44: kkk | J44: Colour: | K44: SUPERIOR WHITE
B45: p | C45: Cubic capacity | G45: 998
B46: 3 | C46: DRIVER'S PARTICULARS | F46: : | G46: DL Original Checked & Found In Order
B47: a | C47: Name of Driver | F47: : | G47: JANG SINGH | J47: DOB: | K47: 25.07.1994
C48: Address | F48: : | G48: VILL. KARANPUR PO NΑΝΑKPUR, Pinjore (MC), Kalka, Panchkula, HR, 133302
...

Sheet Sheet2
G3: MOTOR SURVEY REPORT
B6: INSURER | F6: =Sheet1!G13 -> NA
B7: ADDRESS | F7: =Sheet1!G14 -> 0
F8: =Sheet1!G15 -> 0
B10: INSURED | F10: =Sheet1!G18 -> NA
B12: VEHICLE REG. NO. | F12: =Sheet1!G25 -> HR49H9873
B14: C.NOTE/POLICY NO. | F14: =Sheet1!G16 -> NA
B16: PERIOD | F16: =Sheet1!K16 -> NA
B18: DATE OF LOSS | F18: =Sheet1!G57 -> NA
B26: PAYMENT TO BE MADE IN THE FAVOUR OF REPAIRER
B42: REPORT SUBMITTED BY:
B46: Er. SUNIL KUMAR | G46: # 304, Village: Daria,
B47: SURVEYOR & LOSS ASSESSOR | G47: Near Railway Station, Chandigarh
B48: LICENCE NO: 73070 EXPIRY: 08.02.2028 | G48: Mobile: 098761-35253
B49: PAN NO: AQUPK1480C | G49: e-mail:- ksunilsurveyor@gmail.com

Sheet Sheet5
C3: Er. SUNIL KUMAR | J3: # 304, Village: Daria,
C4: SURVEYOR & LOSS ASSESSOR | J4: Near Railway Station, Chandigarh
C5: LICENCE NO: 73070 EXPIRY: 08.02.2028 | J5: Mobile: 098761-35253
C6: PAN NO: AQUPK1480C | J6: E-mail: ksunilsurveyor@gmail.com
C10: Ref: | D10: =Sheet1!C8 -> SK/2025-26/OICL/9873 | K10: Date: | L10: =Sheet1!K8 -> 0
F12: SURVEY FEE BILL
C15: INSURED | G15: =Sheet1!G18 -> NA
G16: =Sheet1!G19 -> delhi
C18: INSURERS | G18: =Sheet1!G13 -> NA
G19: =Sheet1!G14 -> 0
G20: =Sheet1!G15 -> 0
C22: VEHICLE/ITEM | G22: =Sheet1!G25 -> HR49H9873
C23: Make & Year of Manufacturer | G23: =Sheet1!G31 -> MARUTI ALTO K10 VXI
C25: C NOTE/POLICY NO. | G25: =Sheet1!G16 -> NA | J25: Period: | K25: =Sheet1!K16 -> NA
C28: PROFESSIONAL FEE | G28: Rs | H28: 1800
C30: CONVEYANCE CHARGES | G30: Rs | H30: 500
C32: PHOTOGRAPHS | E32: (20x10=200.00) | G32: Rs | H32: 200
C33: (Digital Photographs)
C35: DAILY ALLOWANCE | G35: Rs | H35: 0
C37: MISCELLANEOUS | G37: Rs | H37: 0
H38: ----------------------
F39: TOTAL | G39: Rs | H39: =SUM(H28:H37) -> 2500
H40: ----------------------
C44: SURVEYOR CODE: | F44: SU00033917
C48: FOR NEFT PAYMENT | J48: (SUNIL KUMAR)
C50: BANK ACCOUNT DETAILS
C51: BANK NAME: | E51: BANK OF INDIA
C52: A/C NUMBER: | E52: 620110110000751
C53: A/C TYPE: | E53: SAVING
C54: IFSC CODE: | E54: BKID0006201
C55: MICRO CODE: | E55: 160013003

Sheet Sheet3
B3: CASHLESS----PAYMENT TO:- | I3: =Sheet1!G68 -> Govind Motor
A6: 1 | B6: INSURED NAME | F6: : | G6: =Sheet1!G18 -> NA
A7: 2 | B7: POLICY NO. & PERIOD | F7: : | G7: =Sheet1!G16 -> NA | J7: Period: | K7: =Sheet1!K16 -> NA
A8: 3 | B8: VEHICLE NO. | F8: : | G8: =Sheet1!G25 -> HR49H9873
A9: 4 | B9: DATE OF LOSS | F9: : | G9: =Sheet1!G57 -> NA
A10: 5 | B10: BILL GENERATION DATE | F10: :
F11: :
B12: LIST OF DOCUMENTS CHECK AND FOUIND IN ORDER
A14: 1 | B14: SURVEOR DEPUTATION | F14: : | G14: Attached
A15: 2 | B15: INTIMATION | F15: : | G15: Attached
A16: 3 | B16: CLAIM FORM | F16: : | G16: Attached
A17: 4 | B17: POLICY COPY | F17: : | G17: Attached
A18: 5 | B18: PREVIOUS POLICY | F18: : | G18: Attached
A19: 6 | B19: TP POLICY (BUNDLED) | F19: : | G19: Attached
A20: 7 | B20: 64VB | F20: : | G20: Attached
A21: 8 | B21: NO CLAIM BONUS | F21: : | G21: NIL
A22: 9 | B22: GAP REPORT | F22: : | G22: N.A.
A23: 10 | B23: DL & RC | F23: : | G23: Attached
A24: 11 | B24: ONLINE VERIFICATION | F24: : | G24: Attached
A25: 12 | B25: ONLY FOR COMERCIAL VEHICLE | F25: : | G25: PERMIT | J25: N.A.
G26: MV TAX | J26: N.A.
G27: STATE ENTRY TAX | J27: N.A.
G28: AUTHORIZATION | J28: N.A.
G29: FITNESS | J29: N.A.
G30: STATE ENTRY TAX | J30: N.A.
A31: 13 | B31: NO TP LOSS AFFIDAVIT | F31: : | G31: N.A.
A32: 14 | B32: KYC FORM (PAN +AADHAR) | F32: : | G32: N.A. | I32: PAN+AADHAR | K32: Attached
A33: 15 | B33: PHOTOGRAPHS | F33: : | G33: Attached
A34: 16 | B34: SURVEY REPORT | F34: : | G34: Attached
A35: 17 | B35: SURVEY FEE BILL | F35: : | G35: Attached
A36: 18 | B36: ESTIMATE | F36: : | G36: Attached
A37: 19 | B37: REPAIR INVOICE | F37: : | G37: Attached
A38: 20 | B38: DEPRECIATION RECIEPT | F38: :
A39: 21 | B39: INVOICE NO PART | F39: :
A40: 22 | B40: INVOICE NO PART | F40: :
A41: 23 | B41: ANY OTHER DOCUMENT | F41: :
A42: 24 | B42: NO. OF CLAIM | F42: :
B44: DETAIL OF ASSESSMENT
B46: PARTS ALLOWED | F46: : | G46: =Sheet1!G174 -> 4074.6698
B47: TOWING CHARGES | F47: : | G47: 0
...

Sheet Sheet4
B3: VEHICLE NO.: | C3: =Sheet1!G25 -> HR49H9873
B6: SUMMARRY OF GST:
B8: GST % ON PARTS | C8: ACTUAL ALLOWED | D8: C GST | E8: SGDT | F8: I GST | G8: TOTAL
B9: 0.18 | C9: =Sheet1!G135+Sheet1!H135+Sheet1!I135 -> 3703.11 | D9: =9*C9/100 -> 333.2799 | E9: =D9 -> 333.2799 | F9: 0 | G9: =D9+E9 -> 666.5598
B10: GRAND TOTAL | C10: =SUM(C9) -> 3703.11 | D10: =SUM(D9) -> 333.2799 | E10: =SUM(E9) -> 333.2799 | F10: 0 | G10: =SUM(G9) -> 666.5598
B13: LABOUR | C13: ACTUAL ALLOWED | D13: C GST | E13: SGDT | F13: I GST | G13: TOTAL
B14: LABOUR 18% | C14: =Sheet1!H164 -> 0 | D14: =9*C14/100 -> 0 | E14: =D14 -> 0 | F14: 0 | G14: =D14+E14 -> 0
B15: GRAND TOTAL | C15: =SUM(C14) -> 0 | D15: =SUM(D14) -> 0 | E15: =SUM(E14) -> 0 | F15: 0 | G15: =SUM(G14) -> 0

Sheet Sheet6

Sheet Sheet7
B2: Er. SUNIL KUMAR | I2: # 304, Village: Daria,
B3: SURVEYOR & LOSS ASSESSOR | I3: Near Railway Station, Chandigarh
B4: LICENCE NO: 73070 EXPIRY: 08.02.2028 | I4: Mobile: 098761-35253
B5: PAN NO: AQUPK1480C | I5: e-mail:- ksunilsurveyor@gmail.com
B8: Ref: | C8: =Sheet1!C8 -> SK/2025-26/OICL/9873 | J8: Date: | K8: =Sheet1!K8 -> 0
B10: PRIVATE & CONFIDENTIAL MOTOR RE-INSPECTION SURVEY REPORT
B11: The report is issued by me as Licenced surveyor without prejudice in respect of cause, nature & extent of loss/damages and subject to the terms and conditions of Insurance Policy.
B13: To, | O13: hello | P13: 1500
B17: Sub: | C17: Reinspection of | E17: =Sheet1!G25 -> HR49H9873
C18: A/C | D18: =Sheet1!G18 -> NA | H18: Date of Accident: | J18: =Sheet1!N57 -> 0
C19: C. No. | D19: =Sheet1!G16 -> NA | G19: Period: | H19: =Sheet1!K16 -> NA
B21: Sir,
B24: Fllowing are the details:
B26: 1 | C26: Whether all parts allowed for replacement by final survey report have been actually been replaced
C27: with the new parts. The details are as under:
B29: S.N. | C29: Particulars | F29: Remarks | G29: Salvage
B59: 2 | C59: Salvage:
B62: 3 | C62: Labour/Repair
B75: 4 | C75: Remarks
B78: The re-inspection report is " without prejudice"
B80: Thanking you
B84: Er. SUNIL KUMAR
B87: Enclosures:
B88: 1 | C88: Final survey report
B89: 2 | C89: Re-inspection report & photographs
B90: 3 | C90: Survey fee bill
B92: I have physically verified the following Major Assembilies:
B94: Chassis No. | D94: =Sheet1!G29 -> S00546022
B95: Engine No. | D95: =Sheet1!G30 -> N8272201
